Workbook
Name Personeller: [1]!Tablo2[Ad Soyad]

Sheet Dashboard
H12: #VALUE!

Sheet Products
I3: Product Name | J3: Product Model | K3: Price | L3: Stock
I4: Audi | J4: A7 | K4: 6000000 | L4: 2
I5: Audi | J5: A5 | K5: 3500000 | L5: 5
I6: BMW | J6: X6 | K6: 2100000 | L6: 1
I7: Mercedes | J7: CLA | K7: 1630000 | L7: 2
I8: BMW | J8: 320i | K8: 1850000 | L8: 3
I9: BMW | J9: 520d | K9: 2950000 | L9: 2
I10: BMW | J10: X3 | K10: 3100000 | L10: 1
I11: BMW | J11: X5 | K11: 4650000 | L11: 2
H12: #VALUE! | I12: BMW | J12: M4 | K12: 6250000 | L12: 1
I13: Audi | J13: A3 | K13: 1550000 | L13: 4
I14: Audi | J14: A4 | K14: 2450000 | L14: 3
I15: Audi | J15: A6 | K15: 4100000 | L15: 2
I16: Audi | J16: Q3 | K16: 2850000 | L16: 3
I17: Audi | J17: Q7 | K17: 5200000 | L17: 1
I18: Mercedes | J18: C200 | K18: 2650000 | L18: 3
I19: Mercedes | J19: E300 | K19: 4350000 | L19: 2
I20: Mercedes | J20: GLA | K20: 2950000 | L20: 4
I21: Mercedes | J21: GLC | K21: 3850000 | L21: 2
I22: Mercedes | J22: S400 | K22: 7850000 | L22: 1
I23: Volkswagen | J23: Golf | K23: 1450000 | L23: 5
I24: Volkswagen | J24: Passat | K24: 2150000 | L24: 3
... I50: Opel | J50: Astra | K50: 1450000 | L50: 6

Sheet Sales
I7: Tarih | J7: Satış Personeli | K7: Müşteri Adı | L7: Müşteri Konumu | M7: Marka | N7: Modeli | O7: Liste Fiyatı | P7: İskonto | Q7: Satış Fiyatı | R7: Adet | S7: Toplam Tutar
I8: 45155 | J8: Emre Akyüz | K8: Ahmet Tekin | L8: İzmir | M8: Audi | N8: A5 | O8: =VLOOKUP(Tablo4[[#This Row],[Modeli]],Products!J4:K48,2,0) -> 3500000 | P8: 0.01 | Q8: =Tablo4[[#This Row],[Liste Fiyatı]]*(1-Tablo4[[#This Row],[İskonto]]) -> 3465000 | R8: 5 | S8: =Tablo4[[#This Row],[Satış Fiyatı]]*Tablo4[[#This Row],[Adet]] -> 17325000
I9: 45170 | J9: Emre Akyüz | K9: Emre Ağmil | L9: İzmir | M9: Hyundai | N9: i20 | O9: =VLOOKUP(Tablo4[[#This Row],[Modeli]],Products!J5:K49,2,0) -> 1050000 | P9: 0.02 | Q9: =Tablo4[[#This Row],[Liste Fiyatı]]*(1-Tablo4[[#This Row],[İskonto]]) -> 1029000 | R9: 2 | S9: =Tablo4[[#This Row],[Satış Fiyatı]]*Tablo4[[#This Row],[Adet]] -> 2058000
I10: 45175 | J10: Akif Karaca | K10: Betül Alpaslan | L10: İzmir | M10: Renault | N10: Megane | O10: =VLOOKUP(Tablo4[[#This Row],[Modeli]],Products!J6:K50,2,0) -> 1050000 | P10: 0.01 | Q10: =Tablo4[[#This Row],[Liste Fiyatı]]*(1-Tablo4[[#This Row],[İskonto]]) -> 1039500 | R10: 3 | S10: =Tablo4[[#This Row],[Satış Fiyatı]]*Tablo4[[#This Row],[Adet]] -> 3118500
I11: 45177 | J11: Akif Karaca | K11: Bekir Çolak | L11: Ankara | M11: Nissan | N11: i20 | O11: =VLOOKUP(Tablo4[[#This Row],[Modeli]],Products!J7:K55,2,0) -> 1050000 | P11: 0.02 | Q11: =Tablo4[[#This Row],[Liste Fiyatı]]*(1-Tablo4[[#This Row],[İskonto]]) -> 1029000 | R11: 6 | S11: =Tablo4[[#This Row],[Satış Fiyatı]]*Tablo4[[#This Row],[Adet]] -> 6174000
I12: 45206 | J12: Zeynep Yılmaz | K12: Emine Karahan | L12: Erzurum | M12: Opel | N12: Astra | O12: =VLOOKUP(Tablo4[[#This Row],[Modeli]],Products!J8:K56,2,0) -> 1450000 | P12: 0.005 | Q12: =Tablo4[[#This Row],[Liste Fiyatı]]*(1-Tablo4[[#This Row],[İskonto]]) -> 1442750 | R12: 3 | S12: =Tablo4[[#This Row],[Satış Fiyatı]]*Tablo4[[#This Row],[Adet]] -> 4328250
I13: 44927 | J13: Zeynep Yılmaz | K13: Ayça Ersoy | L13: Trabzon | M13: Opel | N13: Corsa-e | O13: =VLOOKUP(Tablo4[[#This Row],[Modeli]],Products!J9:K57,2,0) -> 1850000 | P13: 0.02 | Q13: =Tablo4[[#This Row],[Liste Fiyatı]]*(1-Tablo4[[#This Row],[İskonto]]) -> 1813000 | R13: 2 | S13: =Tablo4[[#This Row],[Satış Fiyatı]]*Tablo4[[#This Row],[Adet]] -> 3626000
I14: 44958 | J14: Ahmet Yavuz | K14: Emre Saydık | L14: Bursa | M14: Ford | N14: Kuga | O14: =VLOOKUP(Tablo4[[#This Row],[Modeli]],Products!J10:K58,2,0) -> 2550000 | P14: 0.01 | Q14: =Tablo4[[#This Row],[Liste Fiyatı]]*(1-Tablo4[[#This Row],[İskonto]]) -> 2524500 | R14: 6 | S14: =Tablo4[[#This Row],[Satış Fiyatı]]*Tablo4[[#This Row],[Adet]] -> 15147000
I15: 44963 | J15: Emre Akyüz | K15: Arif Bilen | L15: İzmir | M15: Hyundai | N15: i20 | O15: =VLOOKUP(Tablo4[[#This Row],[Modeli]],Products!J11:K59,2,0) -> 1050000 | P15: 0.01 | Q15: =Tablo4[[#This Row],[Liste Fiyatı]]*(1-Tablo4[[#This Row],[İskonto]]) -> 1039500 | R15: 5 | S15: =Tablo4[[#This Row],[Satış Fiyatı]]*Tablo4[[#This Row],[Adet]] -> 5197500
I16: 44993 | J16: Akif Karaca | K16: Deniz Karahan | L16: İstanbul | M16: Volkswagen | N16: Arteon | O16: =VLOOKUP(Tablo4[[#This Row],[Modeli]],Products!J12:K60,2,0) -> 3250000 | P16: 0.02 | Q16: =Tablo4[[#This Row],[Liste Fiyatı]]*(1-Tablo4[[#This Row],[İskonto]]) -> 3185000 | R16: 8 | S16: =Tablo4[[#This Row],[Satış Fiyatı]]*Tablo4[[#This Row],[Adet]] -> 25480000
I17: 44992 | J17: Emre Akyüz | K17: Berat El | L17: Bursa | M17: Volkswagen | N17: Tiguan | O17: =VLOOKUP(Tablo4[[#This Row],[Modeli]],Products!J13:K61,2,0) -> 2650000 | P17: 0.005 | Q17: =Tablo4[[#This Row],[Liste Fiyatı]]*(1-Tablo4[[#This Row],[İskonto]]) -> 2636750 | R17: 7 | S17: =Tablo4[[#This Row],[Satış Fiyatı]]*Tablo4[[#This Row],[Adet]] -> 18457250

Sheet Staff
I7: Ad Soyad | J7: Bölge | K7: Prim Limiti | L7: Prim Yüzdesi | M7: Toplam Satış Tutarı | N7: Hakedilen Prim
I8: Emre Akyüz | J8: Ege | K8: 3000000 | L8: 0.01 | M8: =IFERROR( SUMIFS( Tablo4[Toplam Tutar], Tablo4[Satış Personeli], Tablo4[[#This Row],[Satış Personeli]]), "Satış Bulunamadı") -> 43037750 | N8: =IFERROR(Tablo5[[#This Row],[Toplam Satış Tutarı]]*Tablo5[[#This Row],[Prim Yüzdesi]],"Satış Bulunamadı") -> 430377.5
I9: Ahmet Yavuz | J9: Ege | K9: 4000000 | L9: 0.02 | M9: =IFERROR( SUMIFS( Tablo4[Toplam Tutar], Tablo4[Satış Personeli], Tablo4[[#This Row],[Satış Personeli]]), "Satış Bulunamadı") -> 43037750 | N9: =IFERROR(Tablo5[[#This Row],[Toplam Satış Tutarı]]*Tablo5[[#This Row],[Prim Yüzdesi]],"Satış Bulunamadı") -> 860755
I10: Aslı Kara | J10: Marmara | K10: 4000000 | L10: 0.01 | M10: =IFERROR( SUMIFS( Tablo4[Toplam Tutar], Tablo4[Satış Personeli], Tablo4[[#This Row],[Satış Personeli]]), "Satış Bulunamadı") -> 34772500 | N10: =IFERROR(Tablo5[[#This Row],[Toplam Satış Tutarı]]*Tablo5[[#This Row],[Prim Yüzdesi]],"Satış Bulunamadı") -> 347725
I11: Akif Karaca | J11: Marmara | K11: 4500000 | L11: 0.02 | M11: =IFERROR( SUMIFS( Tablo4[Toplam Tutar], Tablo4[Satış Personeli], Tablo4[[#This Row],[Satış Personeli]]), "Satış Bulunamadı") -> 34772500 | N11: =IFERROR(Tablo5[[#This Row],[Toplam Satış Tutarı]]*Tablo5[[#This Row],[Prim Yüzdesi]],"Satış Bulunamadı") -> 695450
I12: Ayça Karakuzu | J12: Marmara | K12: 3000000 | L12: 0.02 | M12: =IFERROR( SUMIFS( Tablo4[Toplam Tutar], Tablo4[Satış Personeli], Tablo4[[#This Row],[Satış Personeli]]), "Satış Bulunamadı") -> 7954250 | N12: =IFERROR(Tablo5[[#This Row],[Toplam Satış Tutarı]]*Tablo5[[#This Row],[Prim Yüzdesi]],"Satış Bulunamadı") -> 159085
I13: Zeynep Yılmaz | J13: Karadeniz | K13: 4000000 | L13: 0.01 | M13: =IFERROR( SUMIFS( Tablo4[Toplam Tutar], Tablo4[Satış Personeli], Tablo4[[#This Row],[Satış Personeli]]), "Satış Bulunamadı") -> 7954250 | N13: =IFERROR(Tablo5[[#This Row],[Toplam Satış Tutarı]]*Tablo5[[#This Row],[Prim Yüzdesi]],"Satış Bulunamadı") -> 79542.5
H50: #VALUE!

Sheet Database
B1: Toplam Ciro | C1: =$B$11 -> 100911500
B2: Toplam Satılan Tutar | C2: =$C$11 -> 47
A6: Satır Etiketleri | B6: Total Sales Price | C6: Total Sales
A7: Zeynep Yılmaz | B7: 7954250 | C7: 5
A8: Ahmet Yavuz | B8: 15147000 | C8: 6
A9: Akif Karaca | B9: 34772500 | C9: 17
A10: Emre Akyüz | B10: 43037750 | C10: 19
A11: General | B11: 100911500 | C11: 47
A14: Satır Etiketleri | B14: Total Sales
A15: Oca | B15: 2
A16: Şub | B16: 11
A17: Mar | B17: 15
A18: Ağu | B18: 5
A19: Eyl | B19: 11
A20: Eki | B20: 3
A21: General | B21: 47
A25: Satır Etiketleri | B25: Toplam Toplam Tutar
A26: Renault | B26: 3118500
A27: Nissan | B27: 6174000
A28: Hyundai | B28: 7255500
A29: Opel | B29: 7954250
A30: Ford | B30: 15147000
A31: Audi | B31: 17325000
A32: Volkswagen | B32: 43937250
A33: General | B33: 100911500
A36: Satır Etiketleri | B36: Toplam Toplam Tutar
A37: Ahmet Yavuz | B37: 15147000
A38: Akif Karaca | B38: 34772500
A39: Emre Akyüz | B39: 43037750
A40: Zeynep Yılmaz | B40: 7954250
A41: General | B41: 100911500
A44: Satır Etiketleri | B44: Toplam Adet
A45: i20 | B45: 13
A46: Arteon | B46: 8
A47: Tiguan | B47: 7
A48: Kuga | B48: 6
A49: A5 | B49: 5
A50: Megane | B50: 3
A51: Astra | B51: 3
A52: Corsa-e | B52: 2
...
